schematic = {
	size = {x=3, y=3, z=3},
	yslice_prob = {
		{ypos=0, prob=254},
		{ypos=1, prob=254},
		{ypos=2, prob=254},
	},
	data = {
		{name="dungeon:stone_block", prob=254, param2=0},
		{name="dungeon:stone_block", prob=254, param2=0},
		{name="dungeon:stone_block", prob=254, param2=0},
		{name="air", prob=254, param2=0},
		{name="air", prob=254, param2=0},
		{name="air", prob=254, param2=0},
		{name="air", prob=254, param2=0},
		{name="air", prob=254, param2=0},
		{name="air", prob=254, param2=0},
		{name="dungeon:stone_block", prob=254, param2=0},
		{name="dungeon:stone_block", prob=254, param2=0},
		{name="dungeon:stone_block", prob=254, param2=0},
		{name="air", prob=254, param2=0},
		{name="air", prob=254, param2=0},
		{name="air", prob=254, param2=0},
		{name="air", prob=254, param2=0},
		{name="air", prob=254, param2=0},
		{name="air", prob=254, param2=0},
		{name="dungeon:stone_block", prob=254, param2=0},
		{name="dungeon:stone_block", prob=254, param2=0},
		{name="dungeon:stone_block", prob=254, param2=0},
		{name="air", prob=254, param2=0},
		{name="air", prob=254, param2=0},
		{name="air", prob=254, param2=0},
		{name="air", prob=254, param2=0},
		{name="air", prob=254, param2=0},
		{name="air", prob=254, param2=0},
	},
}
